[2025-08-20T17:03:15.674+0000] {local_task_job_runner.py:120} INFO - ::group::Pre task execution logs
[2025-08-20T17:03:15.700+0000] {taskinstance.py:2076} INFO - Dependencies all met for dep_context=non-requeueable deps ti=<TaskInstance: weather_avg_temp.fetch_avg scheduled__2025-08-19T00:00:00+00:00 map_index=1 [queued]>
[2025-08-20T17:03:15.706+0000] {taskinstance.py:2076} INFO - Dependencies all met for dep_context=requeueable deps ti=<TaskInstance: weather_avg_temp.fetch_avg scheduled__2025-08-19T00:00:00+00:00 map_index=1 [queued]>
[2025-08-20T17:03:15.706+0000] {taskinstance.py:2306} INFO - Starting attempt 3 of 3
[2025-08-20T17:03:15.714+0000] {taskinstance.py:2330} INFO - Executing <Mapped(_PythonDecoratedOperator): fetch_avg> on 2025-08-19 00:00:00+00:00
[2025-08-20T17:03:15.722+0000] {standard_task_runner.py:90} INFO - Running: ['***', 'tasks', 'run', 'weather_avg_temp', 'fetch_avg', 'scheduled__2025-08-19T00:00:00+00:00', '--job-id', '21', '--raw', '--subdir', 'DAGS_FOLDER/weather_avg_temp_dag.py', '--cfg-path', '/tmp/tmp196g9ghz', '--map-index', '1']
[2025-08-20T17:03:15.723+0000] {standard_task_runner.py:91} INFO - Job 21: Subtask fetch_avg
[2025-08-20T17:03:15.724+0000] {logging_mixin.py:188} WARNING - /home/***/.local/lib/python3.12/site-packages/***/task/task_runner/standard_task_runner.py:61 DeprecationWarning: This process (pid=173) is multi-threaded, use of fork() may lead to deadlocks in the child.
[2025-08-20T17:03:15.724+0000] {standard_task_runner.py:63} INFO - Started process 178 to run task
[2025-08-20T17:03:15.759+0000] {task_command.py:426} INFO - Running <TaskInstance: weather_avg_temp.fetch_avg scheduled__2025-08-19T00:00:00+00:00 map_index=1 [running]> on host fbf18af1ad57
[2025-08-20T17:03:15.824+0000] {taskinstance.py:2648} INFO - Exporting env vars: AIRFLOW_CTX_DAG_OWNER='data-eng' AIRFLOW_CTX_DAG_ID='weather_avg_temp' AIRFLOW_CTX_TASK_ID='fetch_avg' AIRFLOW_CTX_EXECUTION_DATE='2025-08-19T00:00:00+00:00' AIRFLOW_CTX_TRY_NUMBER='3' AIRFLOW_CTX_DAG_RUN_ID='scheduled__2025-08-19T00:00:00+00:00'
[2025-08-20T17:03:15.825+0000] {taskinstance.py:430} INFO - ::endgroup::
[2025-08-20T17:03:16.140+0000] {taskinstance.py:441} INFO - ::group::Post task execution logs
[2025-08-20T17:03:16.140+0000] {taskinstance.py:2905} ERROR - Task failed with exception
Traceback (most recent call last):
  File "/home/airflow/.local/lib/python3.12/site-packages/airflow/models/taskinstance.py", line 465, in _execute_task
    result = _execute_callable(context=context, **execute_callable_kwargs)
             ^^^^^^^^^^^^^^^^^^^^^^^^^^^^^^^^^^^^^^^^^^^^^^^^^^^^^^^^^^^^^
  File "/home/airflow/.local/lib/python3.12/site-packages/airflow/models/taskinstance.py", line 432, in _execute_callable
    return execute_callable(context=context, **execute_callable_kwargs)
           ^^^^^^^^^^^^^^^^^^^^^^^^^^^^^^^^^^^^^^^^^^^^^^^^^^^^^^^^^^^^
  File "/home/airflow/.local/lib/python3.12/site-packages/airflow/models/baseoperator.py", line 401, in wrapper
    return func(self, *args, **kwargs)
           ^^^^^^^^^^^^^^^^^^^^^^^^^^^
  File "/home/airflow/.local/lib/python3.12/site-packages/airflow/decorators/base.py", line 265, in execute
    return_value = super().execute(context)
                   ^^^^^^^^^^^^^^^^^^^^^^^^
  File "/home/airflow/.local/lib/python3.12/site-packages/airflow/models/baseoperator.py", line 401, in wrapper
    return func(self, *args, **kwargs)
           ^^^^^^^^^^^^^^^^^^^^^^^^^^^
  File "/home/airflow/.local/lib/python3.12/site-packages/airflow/operators/python.py", line 235, in execute
    return_value = self.execute_callable()
                   ^^^^^^^^^^^^^^^^^^^^^^^
  File "/home/airflow/.local/lib/python3.12/site-packages/airflow/operators/python.py", line 252, in execute_callable
    return self.python_callable(*self.op_args, **self.op_kwargs)
           ^^^^^^^^^^^^^^^^^^^^^^^^^^^^^^^^^^^^^^^^^^^^^^^^^^^^^
  File "/opt/airflow/dags/weather_avg_temp_dag.py", line 43, in fetch_avg
    payload = client.get_city_forecast(query, days=days)
              ^^^^^^^^^^^^^^^^^^^^^^^^^^^^^^^^^^^^^^^^^^
  File "/opt/airflow/app/src/weatheravg/client.py", line 93, in get_city_forecast
    raise WeatherAPIError(f"HTTP {resp.status_code} for {city_query!r} (days={days}). Body: {snippet}")
weatheravg.client.WeatherAPIError: HTTP 400 for 'Los Angeles, CA' (days=6). Body: {"error":{"code":1006,"message":"No matching location found."}}
[2025-08-20T17:03:16.148+0000] {taskinstance.py:1206} INFO - Marking task as FAILED. dag_id=weather_avg_temp, task_id=fetch_avg, run_id=scheduled__2025-08-19T00:00:00+00:00, map_index=1, execution_date=20250819T000000, start_date=20250820T170315, end_date=20250820T170316
[2025-08-20T17:03:16.155+0000] {standard_task_runner.py:110} ERROR - Failed to execute job 21 for task fetch_avg (HTTP 400 for 'Los Angeles, CA' (days=6). Body: {"error":{"code":1006,"message":"No matching location found."}}; 178)
[2025-08-20T17:03:16.178+0000] {local_task_job_runner.py:240} INFO - Task exited with return code 1
[2025-08-20T17:03:16.197+0000] {taskinstance.py:3503} INFO - 0 downstream tasks scheduled from follow-on schedule check
[2025-08-20T17:03:16.199+0000] {local_task_job_runner.py:222} INFO - ::endgroup::
